Workbook

Sheet Assumptions
A1: SSV Admin Cost Model — Assumptions
A2: Blue = hardcoded input | Formulas reference these cells. All inputs marked ✓ Sourced or ~ Estimated.
A3: DET Casual Relief Teacher (CRT) Rates
A4: CRT daily rate ($) | B4: 425.8 | C4: ✓ Sourced | D4: DET Victoria rate effective July 2025 — Kirsteen Farrance email 05/11/2021 + DET website
A5: CRT hourly rate ($) | B5: 70.97 | C5: ✓ Sourced | D5: Daily rate ÷ 6 hrs teaching = $70.97; full day = 7.5 hrs contracted
A6: Working hrs per day | B6: 7.5 | C6: ✓ Sourced | D6: Standard DET contracted day
A7: SSV System Scale (Victoria)
A8: Primary Districts (VIC) | B8: 232 | C8: ✓ Sourced | D8: SSV Primary Schools Resource Manual Feb 2026, p.5 — exact figure
A9: Primary Divisions (VIC) | B9: 55 | C9: ✓ Sourced | D9: SSV 2026-27 Primary Division Coordinator PD — '55 × Primary Division Coordinator positions'
A10: SSV Sporting Regions | B10: 8 | C10: ✓ Sourced | D10: SSV 2026-27 PD lists 8 regions: EMR, Gippsland, GWR, Hume, LME, NMR, SMR, WMR
A11: Primary Region Coordinators | B11: 16 | C11: ~ Estimated | D11: 2 per region (Individual/Summer + Winter Sports) × 8 regions
A12: Schools in VIC | B12: 1600 | C12: ~ Estimated | D12: DET 2024 — ~1,600 government primary schools
A13: Carnivals per year (PE teacher) | B13: 3 | C13: ✓ Sourced | D13: Athletics + Swimming + Cross Country per district cycle
A14: Coordinator Remuneration — SSV Official Position Descriptions (2026-27)
A15: District coordinator pay ($/yr) | B15: 4200 | C15: ✓ Sourced | D15: Local / variable — funded by school membership levies. Wyndham Vale District = $4,200/yr (2024, confirmed email from Sharon Veale, Business Manager). SSV 'Models of Remuneration' guide: Model A = nil, Model E = major. NOT paid by SSV.
A16: Division coordinator pay ($/yr) | B16: 4500 | C16: ✓ Sourced | D16: SSV pays via eduPay up to $4,500. Confirmed: 2026-27 Primary Division Coordinator PD (ssv.vic.edu.au). Also confirmed: Kirsteen Farrance email 23/09/2021 ('up to $4,500 via eduPay'). Paddy received $4,200 in 2024 (Sharon Veale email 18/07/2024).
A17: Region coord. pay — direct ($) | B17: 7500 | C17: ✓ Sourced | D17: SSV pays via eduPay up to $7,500. Confirmed: 2026-27 Primary Region Coordinator Individual/Summer Sports PD (ssv.vic.edu.au).
A18: Region coord. CRT coverage ($/yr) | B18: 6000 | C18: ✓ Sourced | D18: ADDITIONAL: Each school with a Region Coordinator receives up to $6,000/yr for CRT coverage. Confirmed: 2026-27 Primary Region Coordinator PD (ssv.vic.edu.au).
A19: Region coordinator total value | B19: 13500 | C19: ✓ Sourced | D19: =$7,500 direct pay + $6,000 CRT coverage (both from SSV)
A20: Estimated Hours per Role per Year (Admin burden from manual processes)
A21: PE teacher hrs/yr (admin) | B21: 12 | C21: ~ Estimated | D21: Entering results, communicating entries, chasing eligibility. 3 carnivals × ~4 hrs. Conservative.
A22: District coord. hrs/yr | B22: 28 | C22: ~ Estimated | D22: Planning carnival, collecting entries, sending draw, fielding Q&A, re-checking results. ~9 hrs per carnival.
A23: Division coord. hrs/yr | B23: 36 | C23: ~ Estimated | D23: Cross-district coordination, eligibility disputes, Meet Manager re-entry, 4→2 event cliff emails.
A24: Region coord. hrs/yr | B24: 48 | C24: ~ Estimated | D24: Division rollup, state nominations, athlete eligibility across multiple divisions.

Sheet Task Breakdown
A1: Admin Task Breakdown by Role — Sources & Confidence
A2: # | B2: Task | C2: Est. Hrs | D2: Evidence / Source | E2: Confidence
A3: 🏫 PE Teacher (per school, per year)
A4: 1 | B4: Enter student details into school spreadsheet template | C4: 0.5 | D4: Swim/Athletics entry templates emailed from District each term | E4: ✓ Sourced — seen in email evidence
A5: 2 | B5: Collect signed permission/consent forms from parents | C5: 0.5 | D5: David Nahm email: transport consent for cross-country — separate form per student per carnival | E5: ✓ Sourced — email evidence
A6: 3 | B6: Check student eligibility (age groups, event limits) | C6: 0.75 | D6: SSV Manual p.7: 4-event limit at District, 2-event limit at Division creates manual check requirement | E6: ✓ Sourced — SSV Manual
A7: 4 | B7: Format and submit entries to District Coordinator | C7: 0.5 | D7: Required in specific format per District (varies by district) | E7: ✓ Sourced — email evidence
A8: 5 | B8: Communicate carnival details to parents/carers | C8: 0.5 | D8: Nikki Little email: parent complaint re communication — schools responsible for informing parents | E8: ✓ Sourced — email evidence
A9: 6 | B9: Manage 4→2 event negotiation with qualifiers | C9: 1 | D9: At District level students can do 4 events; Division only 2. Each qualifier needing reduction requires parent/student negotiation + District email chain. | E9: ✓ Sourced — Paddy confirmed + email evidence
A10: 7 | B10: Attend carnival on the day (supervision/admin) | C10: 1 | D10: PE teacher accompanies students; handles on-day queries from coordinator | E10: ✓ Sourced — standard duty
A11: 8 | B11: Re-check results after carnival, respond to queries | C11: 0.5 | D11: Mel Camilleri email: results re-check requests after carnival; Jason Maxwell email: staffing queries | E11: ✓ Sourced — email evidence
A12: 9 | B12: Collect and return equipment; submit expense claims | C12: 0.5 | D12: Standard post-carnival admin for school | E12: ~ Estimated
A13: 10 | B13: Organise transport (buses, permission, payments) | C13: 0.5 | D13: David Nahm email: separate transport consent form per student | E13: ✓ Sourced — email evidence
A14: 11 | B14: Archive records for DEECD compliance | C14: 0.25 | D14: Required record-keeping for duty of care | E14: ~ Estimated
A15: 12 | B15: Handle ad-hoc parent and student queries | C15: 0.5 | D15: Nikki Little email: parent escalation; typical PE teacher experience | E15: ✓ Sourced — email evidence
A17: 🏆 District Coordinator (per district, per year)
A18: 1 | B18: Design and distribute entry spreadsheet template to schools | C18: 1 | D18: Templates seen in Paddy's inbox — custom per district, different format each year | E18: ✓ Sourced — email evidence
A19: 2 | B19: Collect and consolidate entries from 6-15 schools | C19: 2 | D19: Williamstown District: 8 schools. Manual copy-paste from individual school submissions. | E19: ✓ Sourced — Drive spreadsheet
A20: 3 | B20: Check entries for eligibility errors (age, events, schools) | C20: 1.5 | D20: Ethan Easow email: wrong school listed; common error requiring manual correction | E20: ✓ Sourced — email evidence
A21: 4 | B21: Chase missing/late school entries (emails, calls) | C21: 1 | D21: Truganina South PS email: school missing from swim draw — follow-up required | E21: ✓ Sourced — email evidence
A22: 5 | B22: Create carnival heat draws and event programmes | C22: 2 | D22: For athletics: manual measurement/cone placement. For swimming: heat sheets per event. Major time sink. | E22: ✓ Sourced — Paddy confirmed
A23: 6 | B23: Book venue and organise logistics (equipment, officials) | C23: 1 | D23: District coordinator responsibility; requires early booking confirmation from schools | E23: ✓ Sourced — standard duty
A24: 7 | B24: Send carnival day programme to all schools | C24: 0.5 | D24: Sent via email to all schools before carnival day | E24: ✓ Sourced — email evidence
A25: 8 | B25: Manage on-day coordination (results, timing, disputes) | C25: 1.5 | D25: Lee Jarvis email: on-day Q&A; Jason Maxwell: staffing arrangements | E25: ✓ Sourced — email evidence
A26: 9 | B26: Enter/transcribe results into spreadsheet post-carnival | C26: 1.5 | D26: Results not auto-captured — manually recorded on paper then re-entered | E26: ✓ Sourced — Paddy confirmed
A27: 10 | B27: Send results to all schools for checking | C27: 0.5 | D27: Division entries email: 'I may have made a mistake or two' — distributed for checking before forwarding | E27: ✓ Sourced — email evidence
A28: 11 | B28: Resolve results disputes and corrections | C28: 1 | D28: Typical: 2-4 correction emails per carnival. Sometimes requires re-measuring or timing review. | E28: ✓ Sourced — email evidence
A29: 12 | B29: Identify qualifiers and enforce 4→2 rule for Division | C29: 1.5 | D29: Each student qualifying in 3-4 events must be reduced to 2 for Division. Manual email chain per student. | E29: ✓ Sourced — Paddy confirmed + SSV Manual p.7
... A32: 15 | B32: Manage relay team selections and notify schools | C32: 0.5 | D32: Rule varies: some districts allow 1 relay team per school, some 2. Ad-hoc query source. | E32: ✓ Sourced — Paddy confirmed
A34: 🥇 Division Coordinator (per division, per year — SSV paid)
A35: 1 | B35: Coordinate appointment across 6-10 districts in division | C35: 0.5 | D35: SSV appoints via formal PD process; coordinator liaises with all district coords | E35: ✓ Sourced — SSV PD
A36: 2 | B36: Collect and consolidate district entries | C36: 2.5 | D36: Each district submits in slightly different format; Division coord manually standardises | E36: ✓ Sourced — Division entries email
A37: 3 | B37: Re-enter all data into Meet Manager (swimming/athletics) | C37: 3 | D37: Meet Manager is NOT connected to district spreadsheets. Full manual re-entry required. Mel Camilleri reinstall email + Sunday night crunch email. | E37: ✓ Sourced — email evidence
A38: 4 | B38: Check eligibility (age group compliance, 2-event cap) | C38: 2 | D38: 4→2 event rule: qualifiers from Districts may have been entered in 4 events; Division coord must reduce to 2 and notify. | E38: ✓ Sourced — Paddy confirmed + SSV Manual
A39: 5 | B39: Chase missing/incorrect entries from districts | C39: 1.5 | D39: Truganina South PS missing from draw: common pattern of missing school requiring urgent fix | E39: ✓ Sourced — email evidence
A40: 6 | B40: Create and distribute heat draws from Meet Manager | C40: 2 | D40: Exported from Meet Manager after manual entry; distributed to all districts | E40: ✓ Sourced — Mel Camilleri email
A41: 7 | B41: Manage results on the day and in Meet Manager | C41: 2 | D41: Sunday night crunch email: results processing after late finish, into night | E41: ✓ Sourced — email evidence
A42: 8 | B42: Distribute results and handle corrections | C42: 1.5 | D42: Results sent to districts; correction requests come back within 48 hrs | E42: ✓ Sourced — email evidence
A43: 9 | B43: Enforce relay rules across districts (1 vs 2 teams) | C43: 0.5 | D43: Rule inconsistency across districts — Division coord must clarify and enforce | E43: ✓ Sourced — Paddy confirmed
A44: 10 | B44: Submit state nominations to Region | C44: 1 | D44: Regional entry format; results from Meet Manager need reformatting for SSV system | E44: ✓ Sourced — SSV process
...

Sheet Cost Model
A1: SSV Admin Cost Model — Annual Statewide Estimate
A2: Blue = hardcoded | Black = formula | Green = cross-sheet reference | All dollar figures represent opportunity cost (coordinator time valued at CRT rate) OR actual SSV/district cash expenditure where noted.
A3: Role | B3: Hrs/Year | C3: CRT Days/Yr | D3: Carnivals/Yr | E3: Hrs/Carnival | F3: Count (VIC) | G3: Cost/Role/Yr ($) | H3: Funding Source | I3: Total VIC Cost ($)
A4: PE Teacher (school) | B4: =Assumptions!B21 | C4: =B4/Assumptions!$B$6 | D4: =Assumptions!B13 | E4: =B4/D4 | F4: =Assumptions!B12 | G4: =B4*Assumptions!$B$5 | H4: School (part of teaching role) | I4: =G4*F4
A5: District Coordinator | B5: =Assumptions!B22 | C5: =B5/Assumptions!$B$6 | D5: =Assumptions!B13 | E5: =B5/D5 | F5: =Assumptions!B8 | G5: =B5*Assumptions!$B$5 | H5: District funds (school levies) — VARIABLE | I5: =G5*F5
A6: Division Coordinator | B6: =Assumptions!B23 | C6: =B6/Assumptions!$B$6 | D6: =Assumptions!B13 | E6: =B6/D6 | F6: =Assumptions!B9 | G6: =B6*Assumptions!$B$5 | H6: SSV pays — up to $4,500/yr via eduPay | I6: =G6*F6
A7: Region Coordinator (direct) | B7: =Assumptions!B24 | C7: =B7/Assumptions!$B$6 | D7: =Assumptions!B13 | E7: =B7/D7 | F7: =Assumptions!B11 | G7: =B7*Assumptions!$B$5 | H7: SSV pays — up to $7,500/yr + $6,000 CRT = $13,500 total value | I7: =G7*F7
A8: TOTAL — Annual statewide admin cost burden | I8: =SUM(I4:I7)
A10: Data Sources & Confidence
A11: 232 districts | B11: ✓ EXACT | C11: SSV Primary Schools Resource Manual, February 2026, p.5: '232 Primary Districts across Victoria'
A12: 55 divisions | B12: ✓ EXACT | C12: SSV 2026-27 Primary Division Coordinator Position Description: '55 × Primary Division Coordinator positions within the eight SSV Sporting Regions'
A13: 8 SSV Regions | B13: ✓ EXACT | C13: SSV 2026-27 PDs list all 8 regions: EMR, Gippsland, GWR, Hume, LME, NMR, SMR, WMR
A14: 16 Region Coords | B14: ~ ESTIMATE | C14: 2 roles per region (Individual/Summer + Winter Sports) × 8 regions = 16. Inferred from separate PDs on SSV website.
A15: $4,500 Division pay | B15: ✓ EXACT | C15: SSV 2026-27 Primary Division Coordinator PD (ssv.vic.edu.au): 'paid via eduPay up to $4,500 as per DE Special Payments'. Also: Kirsteen Farrance email 23/09/2021 + Sharon Veale Business Manager email 18/07/2024 confirming $4,200 actual payment to Paddy as Division Coordinator.
A16: $7,500 + $6,000 Region pay | B16: ✓ EXACT | C16: SSV 2026-27 Primary Region Coordinator Individual/Summer Sports PD (ssv.vic.edu.au): 'paid via eduPay up to $7,500' + 'reimbursement up to $6,000 per year for CRT coverage'
A17: $4,200 District pay | B17: ✓ EXACT (one district) | C17: Sharon Veale (Business Manager) email to Jamie Edwards 18/07/2024: 'payment for Wyndham Vale District position is $4,200' — $1,050/term × 4 terms. This is one specific district. SSV 'Models of Remuneration' guide confirms it varies: Model A = nil to Model E = major reimbursement.
A18: CRT rate $425.80/day | B18: ✓ SOURCED | C18: DET Victoria CRT rate effective July 2025. Also cited in Kirsteen Farrance email 05/11/2021 context.
A19: ~1,600 schools | B19: ~ ESTIMATE | C19: DET 2024 approximate figure for government primary schools in Victoria.
A20: Hours estimates | B20: ~ ESTIMATED | C20: Based on Paddy Gallivan's direct experience as PE teacher + District + Division Coordinator at Williamstown PS. Conservative estimates.
A22: ⚠ IMPORTANT: The 'Total VIC Cost' figures above represent the OPPORTUNITY COST of coordinator time at CRT rates — the true cost of the labour being consumed. SEPARATELY, SSV's actual cash outlay is: 55 × $4,500 = $247,500 (Division) + 16 × $13,500 = $216,000 (Region) = $463,500/yr in direct payments. District coordinator pay is additional, locally-funded, and variable — not counted in SSV's budget.

Sheet SportPortal Savings
A1: SportPortal — What We Actually Save
A2: Task-by-task analysis of what SportPortal eliminates vs what still needs a human. Red = current burden. Green = after SportPortal. What remains: venue booking, on-day presence, financial admin, SSV meetings.
A3: Role | B3: Hrs/Yr NOW | C3: Hrs/Yr SportPortal | D3: Hrs Saved | E3: % Time Saved | F3: Count (VIC) | G3: $ Saved /Role/Yr | H3: Total VIC Savings/Yr | I3: What's GONE vs what's left
A4: 🏫 PE Teacher (per school) | B4: 12 | C4: 2.5 | D4: 9.5 | E4: 0.79166667 | F4: =Assumptions!B12 | G4: =D4*Assumptions!$B$5 | H4: =G4*F4 | I4: ✅ GONE: Online entry form, auto age/event eligibility check, auto 4→2 event flag before submission, live results published instantly, results query emails, entry format issues ⚠️ STAYS (genuinely human): Signed permission/consent forms (legal), telling parents the date/time, buses & transport, attending on the day, equipment return
A5: 🏆 District Coordinator (per district) | B5: 28 | C5: 4 | D5: 24 | E5: 0.85714286 | F5: =Assumptions!B8 | G5: =D5*Assumptions!$B$5 | H5: =G5*F5 | I5: ✅ GONE: Entry template design+emailing, chasing schools to submit, consolidating 6-15 spreadsheets, eligibility error checking, heat draw creation, results re-entry after carnival, sending results for checking, 4→2 qualifier enforcement, reformatting for Division submission, sending programme to schools ⚠️ STAYS (genuinely human): Booking the venue, on-day coordination, collecting school levies & financial reconciliation, pre-season meeting with Division
A6: 🥇 Division Coordinator (per division — SSV paid) | B6: 36 | C6: 6 | D6: 30 | E6: 0.83333333 | F6: =Assumptions!B9 | G6: =D6*Assumptions!$B$5 | H6: =G6*F6 | I6: ✅ GONE: Meet Manager re-entry (entire District → Division data re-keyed, EVERY athlete), consolidating district entries from different formats, eligibility enforcement across districts, 4→2 disputes, heat draw generation, distributing results, chasing correction emails, reformatting for Region/state nominations ⚠️ STAYS (genuinely human): On-day carnival management, SSV + Region coordinator meetings, invoicing SSV via eduPay, year-end handover doc, the rare human escalation that needs judgment
A7: 🌏 Region Coordinator (per role — SSV paid) | B7: 48 | C7: 9.5 | D7: 38.5 | E7: 0.80208333 | F7: =Assumptions!B11 | G7: =D7*Assumptions!$B$5 | H7: =G7*F7 | I7: ✅ GONE: Third Meet Manager re-entry (District → Division → Region — same athletes keyed THREE TIMES), aggregating division nominations, cross-division eligibility variance checking, state team formatting and submission, results distribution across all divisions ⚠️ STAYS (genuinely human): Carnival logistics/venue/officials, SSV head office liaison, mentoring 6-8 Division Coordinators, operating fund reconciliation, CRT budget management ($6k), annual program reporting to SSV
A8: TOTAL — Annual statewide time & cost saved by SportPortal | H8: =SUM(H4:H7)
A10: What Still Requires a Human — After SportPortal
A11: Task | B11: Why it stays manual | C11: Who | D11: Verdict
A12: Venue booking & logistics | B12: Contacting venues, confirming dates, arranging equipment hire, officials, first aid — always a human relationship task. | G12: All roles | I12: Will always need a human
A13: On-day coordination | B13: Managing athletes, parents, officials and disputes on the day of the carnival. Tech assists but can't replace presence. | G13: All roles | I13: Will always need a human
A14: Financial administration | B14: Collecting school levies, reconciling operating fund, invoicing SSV via eduPay ($4,500 Division / $7,500 Region claim), paying officials. | G14: District, Division, Region | I14: Will always need a human
A15: Parent permission/consent forms | B15: Legal duty of care requirement — signed consent for participation and transport per student. Not automatable. | G15: PE Teacher | I15: Legal requirement — stays
A16: SSV & coordinator meetings | B16: Annual appointment meetings, Region/Division coordination calls, SSV strategic direction briefings. | G16: Division, Region | I16: Will always need a human
A17: Human judgment escalations | B17: Rare but real: athlete dispute that can't be resolved by data alone, parent complaint requiring empathy, equipment failure on the day. | G17: All roles | I17: By definition needs human
A18: CRT budget management | B18: Region Coordinators must actively claim and manage the $6,000 CRT reimbursement from SSV — requires school admin coordination. | G18: Region | I18: Administrative process — stays

Sheet Email Audit
A1: Every Email SportPortal Kills — Documented from Paddy's Real Inbox
A2: Every email type documented from Paddy Gallivan's school Outlook inbox (Paddy.Gallivan@education.vic.gov.au). Role: PE Teacher + SSV Williamstown District Coordinator + SSV Hobson's Bay Division Coordinator. Each row = a real email type that SportPortal eliminates or dramatically reduces.
A3: # | B3: Email Type | C3: Volume | D3: Real Example from Inbox | E3: What Triggers It (Root Cause) | F3: SportPortal Fix
A4: 📋 CATEGORY 1: Entry Collection Chain (Every carnival, every district, every year)
A5: 1 | B5: Entry template distribution | C5: 1× per carnival per district | D5: Paddy → 5 District Coordinators: 'Please find attached a District Entry form for the upcoming Division Swim meet at Werribee Outdoor Pool. Please save a copy, label it and email it back to me as soon as you can. DO NOT make any alterations to this document.' (Feb 2026) | E5: No online system — coordinator must create, format and email a spreadsheet template to every district, every carnival. Format rules must be re-stated every time (DOB format, name order, school dropdown). | F5: ✅ Schools submit directly in SportPortal. Coordinator opens dashboard — no template, no email.
A6: 2 | B6: Entry submission (spreadsheet returned) | C6: 4–8× per carnival (one per district) | D6: Chris Lamb → Paddy: 'Hi Paddy, Please find the Division spreadsheet attached. Thanks, Chris' + attachment 144KB (Feb 2026). Mitchel Marley, Cruze Henshaw, Jacinta O'Mealley, Jamie Edwards all reply separately. | E6: Each district coordinator fills in their copy and emails it back. Division coord receives 4-8 separate email + spreadsheet attachments per carnival and must manually consolidate. | F6: ✅ Entries appear in SportPortal in real time. Zero inbox traffic.
A7: 3 | B7: Entry submission — late / not yet received chase | C7: 2–4× per carnival | D7: Paddy's instructions include: 'Please let me know if you will not be able to have your entries completed by [deadline]. Please notify me of any missing schools when submitting.' — pre-emptive chase baked into every email. | E7: No submission tracking. Coordinator has no visibility on who has/hasn't submitted. Must manually chase every deadline. | F7: ✅ Dashboard shows submission status per school/district. Coordinator sees instantly who is outstanding — no chase email needed.
A8: 🔴 CATEGORY 2: Data Errors in Submitted Entries
A9: 4 | B9: Missing DOB | C9: 1–3× per carnival | D9: Paddy (Sent Items) → Mel Camilleri: 'Just found one DOB missing from Truganina District. Okoye 15/06/12' (30/08/2022). Discovered only when transferring to Meet Manager — too late for easy fix. | E9: Spreadsheet has no mandatory field validation. PE teachers leave DOB blank. Not caught until coordinator opens the file and manually checks every row. | F9: ✅ SportPortal form field: DOB required, validated on submission. Blank = can't submit.
A10: 5 | B10: DOB in wrong format | C10: 2–5× per carnival | D10: Paddy's entry instructions explicitly state: 'Please note DOB's need to be in the correct format eg (05/12/2026)' — this instruction exists because it keeps happening wrong (DD/MM/YYYY vs MM/DD/YYYY vs text like '5 Dec 2012'). | E10: Free-text Excel cell. Teachers type in whatever format they know. Meet Manager rejects wrong formats silently, causing wrong age group placement. | F10: ✅ SportPortal uses a date picker. Format is enforced. Age group is calculated automatically — no manual check.
A11: 6 | B11: Wrong school listed for athlete | C11: 1–2× per carnival | D11: Ethan Easow email (previous session): athlete listed under wrong school, spotted by coordinator. Required correction email chain with school PE teacher to confirm and resubmit. | E11: PE teachers copy-paste from old spreadsheets and forget to update the school name. No validation against enrollment data. | F11: ✅ School is pre-selected when a PE teacher logs in — can't be wrong.
A12: 7 | B12: Spelling error in athlete name | C12: 3–6× per carnival | D12: Jacinta O'Mealley (Hoppers Crossing District) → Paddy: 'Just a couple of slight changes to our entry form (spelling correction and change in student participating). I have highlighted the changes in yellow for you so they are easy to find.' Entire spreadsheet re-sent for 2 changes. (Feb 2025) | E12: Names typed manually into Excel. Misspellings only caught after submission. Coordinator must receive an entirely new spreadsheet to make a minor fix. | F12: ✅ PE teacher edits their own submission in SportPortal — live update, no email, no re-sent file.
A13: 8 | B13: Wrong age group / over-age athlete entered | C13: 1–3× per carnival | D13: Age group errors consistently appear in Division entries — athletes entered in wrong heat category because DOB was wrong or misread. Causes re-draw after results. | E13: Age groups calculated manually by coordinator after receiving all entries. No automatic check at point of entry. | F13: ✅ SportPortal calculates age group from DOB at time of entry. Wrong age group = flagged immediately.
A14: 9 | B14: Student in too many events (over 4 at District) | C14: 2–4× per carnival | D14: SSV Manual p.7: District allows up to 4 individual events. Schools regularly enter athletes in 5+ without realising. Coordinator must manually count events per athlete across all entries. | E14: No event limit enforcement in spreadsheets. PE teachers enter everything the student can do — coordinator must manually audit. | F14: ✅ SportPortal enforces event limits at entry. 'You have selected 5 events — maximum is 4' shown in real time.
A15: 🟠 CATEGORY 3: Missing Entries & Draw Errors
A16: 10 | B16: Whole school missing from draw | C16: 1–2× per carnival | D16: Truganina South PS missing from swim draw (confirmed real email from previous session). Spotted by PE teacher after draw was distributed — entire school's athletes missing from heats. | E16: Manual consolidation of spreadsheets. Easy to miss a file or skip a tab. No systematic check that all expected schools are present. | F16: ✅ SportPortal knows which schools are in each district. Missing submission = flagged before draw is generated.
A17: 11 | B17: Whole district missing from draw | C17: ~1× per year | D17: Truganina and Derrimut Districts combined in 2024 Division Swim. Coordinator note: 'Truganina And Derrimut Districts are combining' — had to be communicated manually and managed as a special case each carnival. | E17: District combinations change year to year. No system-level tracking — each time requires a specific verbal/email instruction. | F17: ✅ District groupings are configured in SportPortal per event. Automatic.
A18: 12 | B18: Late entry — athlete missed District due to special circumstance | C18: 1–3× per year | D18: Paddy (Sent Items) → Mel Camilleri: 'I also have one request for Rhys Kane 08/06/2010 from Williamstown Primary for 1500m. He missed District due to COVID. He just finished 6th in the country at Cross Country for Nationals. Wasn't sure where to add him in.' (30/08/2022) | E18: No process for exceptional/late entries. Coordinator must manually handle case-by-case via email to Division coord, who must manually insert into Meet Manager. | F18: ✅ SportPortal has configurable 'late entry' or 'wildcard' submission flag. Division coord approves with one click.
A19: 13 | B19: Athlete entered in wrong event type (e.g. sprint vs distance) | C19: 2–4× per carnival | D19: Common error in athletics: student entered in 100m when they meant 200m, or in Shot Put when they do Discus. Caught during draw creation or on the day. | E19: Free text or poorly-validated dropdowns in Excel. No cross-check against what the student actually does. | F19: ✅ Events configured per carnival. Student selects from defined list — can only pick events that exist.
A20: 🟡 CATEGORY 4: The 4→2 Event Cliff (District allows 4 individual events, Division only allows 2)
A21: 14 | B21: 4→2 notification to PE teacher | C21: Per qualifying athlete (avg 5–10 per carnival) | D21: Paddy (as Division Coord) → PE Teacher: 'Jack Smith has qualified in 100m, 200m, Long Jump and Triple Jump at District. He can only enter 2 events at Division. Please confirm which 2 events he will compete in by [date].' | E21: SSV rule: 4 events at District, max 2 at Division. Every athlete who qualifies in 3–4 events generates a manual email chain. With 8+ schools per district and multiple qualifiers, this is 5–15 emails per carnival. | F21: ✅ SportPortal enforces 2-event cap at Division entry. PE teacher selects 2 from their qualifier's 4 events when submitting. No email needed.
A22: 15 | B22: 4→2 reply from PE teacher confirming event choice | C22: Per qualifying athlete | D22: 'Hi Paddy, Jack would like to do 100m and Long Jump. Thanks, [Teacher]' — each reply requires Paddy to update his spreadsheet/Meet Manager entry manually. | E22: No system to capture the choice. Each reply is a separate email that must be manually actioned. | F22: ✅ Selection made in SportPortal at time of Division entry. Auto-saved.
A23: 16 | B23: 4→2 follow-up (no reply received) | C23: 2–4× per carnival | D23: 'Just following up — I haven't heard back about which 2 events [student] will compete in at Division. Can you please confirm by tomorrow?' — a chase email for every non-response. | E23: No deadline enforcement, no automatic reminder. Coordinator must manually track who has/hasn't responded. | F23: ✅ SportPortal won't accept incomplete Division entry. PE teacher can't submit until event selection is made.
A24: 🟢 CATEGORY 5: Results Distribution & Disputes
A25: 17 | B25: Results sent to all schools for checking | C25: 1× per carnival | D25: 'I may have made a mistake or two' — Division coord emails results to all schools for checking before submitting to Region. Creates a window of 24-48hrs where corrections come back. | E25: No live results system. Results typed manually into spreadsheet, emailed out. Schools check their own athletes — errors only caught retrospectively. | F25: ✅ SportPortal publishes results live. Schools can view their athletes' results immediately. Errors flagged in-app, not via email.
A26: 18 | B26: Results correction request from PE teacher | C26: 3–6× per carnival | D26: PE teacher → Division Coord: 'Hi, I think there's an error with Mia Thompson's 200m time — the stopwatch showed 31.4 but the results show 33.4. Can you check?' Triggers re-check of paper results, update in spreadsheet, re-distribution. | E26: Manual timing and manual results entry means transcription errors are common. Each correction requires: find the paper result → verify → update spreadsheet → re-email. | F26: ✅ Results entered once in SportPortal at source. Timing errors still possible but single source of truth — no transcription layer.
A27: 19 | B27: Parent complaint about result escalated through PE teacher | C27: 1–3× per carnival | D27: Nikki Little email (confirmed real from previous session): parent complaint about a student's result or placement, escalated from parent → PE teacher → District Coord → Division Coord email chain. | E27: No audit trail or dispute mechanism. Parent disputes trigger a multi-hop email chain as each level checks their records. Often unresolvable because paper records are gone. | F27: ✅ SportPortal maintains permanent digital record of all results with timestamps. Dispute resolved by checking the record, not re-tracing a 4-email chain.
A28: 20 | B28: Results programme sent to all schools before carnival | C28: 1× per carnival | D28: Paddy's entry instructions: 'I will be sending out another email that you can forward onto your schools with more information about the day, including a program.' — a separate manual email with PDF attachment to all schools. | E28: Programme only exists once Paddy has manually entered all data into Meet Manager and exported. Sent as a static PDF that becomes outdated the moment a correction is made. | F28: ✅ SportPortal auto-generates programme from entries. Schools access via link — always current.
A29: 🔵 CATEGORY 6: Meet Manager Pain
A30: 21 | B30: Meet Manager reinstall / corruption emergency | C30: ~1–2× per year | D30: Mel Camilleri email (confirmed real, previous session): panic email about Meet Manager needing reinstall before carnival. Desktop software with licence management and installation failures. | E30: Meet Manager is a desktop application. Crashes, reinstalls, licence issues all cause last-minute emergencies before carnivals. No cloud backup. | F30: ✅ SportPortal is browser-based. Nothing to install. No licence. Works on any device with internet.
A31: 22 | B31: Sunday night Meet Manager data entry crunch | C31: ~3× per year (one per carnival type) | D31: Division Coord working late Sunday night re-entering all athlete data from district spreadsheets into Meet Manager before Monday's carnival. Email documented in previous session. | E31: District entries arrive in Excel. Meet Manager cannot import from arbitrary Excel formats. Full manual re-entry required — every athlete, every event, every school. 3–4hrs of work the night before. | F31: ✅ SportPortal IS the draw system. No re-entry. Coordinator reviews and approves with one click.
A32: 23 | B32: Meet Manager version mismatch between coordinators | C32: ~1× per year | D32: Different coordinators running different versions of Meet Manager. Files created in newer version can't be opened in older version — exchange of files breaks down. | E32: Desktop software with paid version updates. Not all districts/divisions on same version. Creates compatibility problems when sharing MM files. | F32: ✅ Single cloud platform. Everyone is always on the same version.
A33: ⚙️ CATEGORY 7: Logistics & Coordination Queries
A34: 24 | B34: Transport consent form distribution and return | C34: 1× per student per carnival | D34: David Nahm email (confirmed real): separate transport consent form required per student per carnival. Distributed by PE teacher, collected, forwarded to coordinator. | E34: Separate paper/PDF process outside of any sport system. Not linked to entry data. Parent who signed consent is not linked to the athlete entry. | F34: ✅ SportPortal integrates consent confirmation at student entry — parent/guardian consent captured online as part of registration. No separate form.
A35: 25 | B35: Bus availability inquiry | C35: 1–2× per carnival | D35: Charlotte Jezard → Paddy: 'Bus Availability Inquiry' for carnival day (confirmed real, Feb 2026). School checking bus availability before committing students to carnival. | E35: Transport logistics are completely disconnected from entry system. Schools must separately confirm bus availability, then separately submit entries — two processes that should be one. | F35: ✅ SportPortal can surface carnival date/transport requirements at entry time so schools know what they need before they commit entries.
A36: 26 | B36: Staffing / day representative confirmation | C36: 1–2× per carnival | D36: Jason Maxwell WMR email (confirmed real): queries about who will be representing/available on the day of carnival for coordination duties. | E36: No system for coordinators to register their day-representative or communicate staffing. Handled via ad-hoc email chain. | F36: ✅ SportPortal coordinator profile includes 'day rep' field. Visible to all relevant coordinators before the carnival.
A37: 27 | B37: Date/scheduling query or confusion | C37: 1–3× per year | D37: Jamie Edwards: 'Our swimming is 25th... I can look ha...' — suggests a date discrepancy between what Jamie thought the swim date was vs what was in the entry email. | E37: Carnival dates communicated via email. Easy to lose in a long thread or confuse between years. No single authoritative calendar that all coordinators reference. | F37: ✅ SportPortal calendar shows all carnival dates per district/division. Single source of truth. No date confusion.
A38: 28 | B38: Coordinator handover / role change notification | C38: ~1× per year | D38: Mary Wisby → Paddy: 'SSV Division Handover' email (confirmed real, July 2021). Outgoing coordinator notifying SSV and Division of changeover. 'I will notify HR. M...' | E38: No system-level coordinator tracking. Role changes handled via email chain. New coordinator inherits ad-hoc email threads, no structured handover of data or history. | F38: ✅ SportPortal coordinator accounts — role reassignment means the new person inherits all historical data instantly. No separate handover required.
A39: ⚠️ CATEGORY 8: Rule Inconsistency Queries
A40: 29 | B40: Relay team count query (1 vs 2 allowed) | C40: 1–2× per carnival type | D40: Paddy's entry instructions: 'If you choose to send two [relay teams] through, please send a second copy of the excel spreadsheet.' — different districts allow 1 or 2 relay teams. PE teachers ask each year. | E40: Relay rules vary by district/division. Not stored anywhere officially. PE teachers ask every year because last year's rule may have changed and there's no authoritative source. | F40: ✅ SportPortal stores relay rules per event per district. Rule displayed at point of entry — no query needed.
...
